Message length : 1
Range of tweet IDs : [ friday , 535663027652022272|535663027652022272|black ]
SELECT ID_str, text FROM tweets WHERE ID_str >= 535663027652022272|535663027652022272|black AND ID_str <= friday
Traceback (most recent call last):
  File "/Users/priya/Desktop/CloudComputing_And_BigData/HWs/Assignment_2/scripts/main_queue.py", line 24, in <module>
    sentiment.sentiment_main(sqs_queue,db_conn,db_cur,conn_sns,topic_arn)
  File "/Users/priya/Desktop/CloudComputing_And_BigData/HWs/Assignment_2/scripts/sentiment_analysis.py", line 90, in sentiment_main
    process_msg(m.get_body(),conn,cur);
  File "/Users/priya/Desktop/CloudComputing_And_BigData/HWs/Assignment_2/scripts/sentiment_analysis.py", line 73, in process_msg
    tweets = get_tweets_from_db(IDRange[0], IDRange[1],conn,cur);
  File "/Users/priya/Desktop/CloudComputing_And_BigData/HWs/Assignment_2/scripts/sentiment_analysis.py", line 19, in get_tweets_from_db
    cur.execute(sql_query);
  File "/Users/priya/anaconda/lib/python2.7/site-packages/pymysql/cursors.py", line 132, in execute
    result = self._query(query)
  File "/Users/priya/anaconda/lib/python2.7/site-packages/pymysql/cursors.py", line 271, in _query
    conn.query(q)
  File "/Users/priya/anaconda/lib/python2.7/site-packages/pymysql/connections.py", line 726, in query
    self._affected_rows = self._read_query_result(unbuffered=unbuffered)
  File "/Users/priya/anaconda/lib/python2.7/site-packages/pymysql/connections.py", line 861, in _read_query_result
    result.read()
  File "/Users/priya/anaconda/lib/python2.7/site-packages/pymysql/connections.py", line 1064, in read
    first_packet = self.connection._read_packet()
  File "/Users/priya/anaconda/lib/python2.7/site-packages/pymysql/connections.py", line 826, in _read_packet
    packet.check_error()
  File "/Users/priya/anaconda/lib/python2.7/site-packages/pymysql/connections.py", line 370, in check_error
    raise_mysql_exception(self._data)
  File "/Users/priya/anaconda/lib/python2.7/site-packages/pymysql/err.py", line 116, in raise_mysql_exception
    _check_mysql_exception(errinfo)
  File "/Users/priya/anaconda/lib/python2.7/site-packages/pymysql/err.py", line 112, in _check_mysql_exception
    raise InternalError(errno, errorvalue)
pymysql.err.InternalError: (1054, u"Unknown column 'black' in 'where clause'")
[Finished in 1.6s with exit code 1]
[shell_cmd: python -u "/Users/priya/Desktop/CloudComputing_And_BigData/HWs/Assignment_2/scripts/main_queue.py"]
[dir: /Users/priya/Desktop/CloudComputing_And_BigData/HWs/Assignment_2/scripts]
[path: /usr/bin:/bin:/usr/sbin:/sbin]